<?xml version="1.0"?>
<robot name="turtle_bot_3">


  <material name="black">
        <color rgba="0.0 0.0 0.0 1"/>
  </material>

  <material name="grey">
    <color rgba="0.3 0.3 0.3 1.0"/>
  </material>

  <material name="red">
    <color rgba="1.0 0.0 0.0 1"/>
  </material>

  <material name="blue">
    <color rgba="0.0 0.0 1.0 1"/>
  </material>

  <material name="green_dark">
    <color rgba="0.0 0.5 0.0 1"/>
  </material>


<!--**** Step One ****-->


  <!-- First Plate -->
  <link name="base_link">
  </link>


  <!-- First Plate -->
  <link name="first_plate">
    <visual>
      <geometry>
        <box size="0.1375 0.1375 0.009"/>
      </geometry>
      <material name="black"/>
    </visual>

    <collision>
        <geometry>
          <box size="0.1357 0.1357 0.009"/>
        </geometry>
    </collision>
  
    <inertial>
        <mass value="0.035"/>
        <origin rpy="0 0 0" xyz="0 0 0"/>
        <inertia ixx="5.537947916666668e-05" ixy="0" ixz="0" iyy="5.537947916666668e-05" iyz="0" izz="0.00011028645833333336"/>
    </inertial>
  </link>

    <joint name="base_link_joint" type="fixed">
        <origin rpy="0 0 0" xyz="0 0 0" />
        <parent link="base_link" />
        <child link="first_plate" />
    </joint>

    <gazebo reference="first_plate">
        <material>Gazebo/Black</material>
        <turnGravityOff>true</turnGravityOff>
    </gazebo>


  <!-- Right motor -->
  <link name="right_motor">
    <visual>
      <geometry>
            <box size="0.0465 0.034 0.0285"/>
      </geometry>
      <material name="grey"/>
    </visual>

    <collision>
        <geometry>
            <box size="0.0465 0.034 0.0285"/>
        </geometry>
    </collision>
  
    <inertial>
        <mass value="0.05"/>
        <origin rpy="0 0 0" xyz="0 0 0"/>
        <inertia ixx="8.201041666666668e-06" ixy="0" ixz="0" iyy="1.239375e-05" iyz="0" izz="1.3826041666666666e-05"/>
    </inertial>
  </link>

    <joint name="right_motor_joint" type="fixed">
        <origin rpy="0 0 0" xyz="-0.020 0.05175 0.0175" />
        <parent link="first_plate" />
        <child link="right_motor" />
    </joint>

    <gazebo reference="right_motor">
        <material>Gazebo/Grey</material>
        <turnGravityOff>true</turnGravityOff>
    </gazebo>

  <!-- Right Wheel axle -->
    <link name="right_axle">      
        <visual>
            <origin rpy="0 1.5707 1.5707" xyz="0 0 0"/>
            <geometry>
                <cylinder length="0.00935" radius="0.01025"/>
            </geometry>
            <material name="grey"/>
        </visual>

        <collision>
            <origin rpy="0 1.5707 1.5707" xyz="0 0 0"/>
            <geometry>
                <cylinder length="0.00935" radius="0.01025"/>
            </geometry>
        </collision>

        <inertial>
            <origin rpy="0 1.5707 1.5707" xyz="0 0 0"/>
            <mass value="0.020"/>
            <inertia ixx="6.710166666666668e-07" ixy="0" ixz="0" iyy="6.710166666666668e-07" iyz="0" izz="1.0506250000000002e-06"/>
        </inertial>

    </link>

    <joint name="right_axle_joint" type="fixed">
        <origin rpy="0 0 0" xyz="-0.012 0.014675 0.001"/>
        <child link="right_axle"/>
        <parent link="right_motor"/>
    </joint>

    <gazebo reference="right_axle">
        <material>Gazebo/Grey</material>
        <turnGravityOff>true</turnGravityOff>
    </gazebo>


  <!-- Right wheel-->
    <link name="right_wheel">      
        <visual>
            <origin rpy="0 1.5707 1.5707" xyz="0 0 0"/>
            <geometry>
                <cylinder length="0.0178" radius="0.033"/>
            </geometry>
            <material name="grey"/>
        </visual>

        <collision>
            <origin rpy="0 1.5707 1.5707" xyz="0 0 0"/>
            <geometry>
                <cylinder length="0.0178" radius="0.033"/>
            </geometry>
        </collision>

        <inertial>
            <origin rpy="0 1.5707 1.5707" xyz="0 0 0"/>
            <mass value="0.025"/>
            <inertia ixx="7.466333333333334e-06" ixy="0" ixz="0" iyy="7.466333333333334e-06" iyz="0" izz="1.3612500000000002e-05"/>
        </inertial>
    </link>

    <gazebo reference="right_wheel">
        <kp>1000000000000000000000000000.0</kp>
        <kd>1000000000000000000000000000.0</kd>
        <mu1>10.0</mu1>
        <mu2>10.0</mu2>
        <material>Gazebo/Grey</material>
        <turnGravityOff>true</turnGravityOff>
    </gazebo>

    <joint name="right_wheel_joint" type="continuous">
        <origin rpy="0 0 0" xyz="0 0.013575 0"/>
        <child link="right_wheel"/>
        <parent link="right_axle"/>
        <axis rpy="0 0 0" xyz="0 1 0"/>
        <limit effort="10000" velocity="1000"/>
        <joint_properties damping="1.0" friction="1.0"/>
    </joint>




  <!-- Left motor -->
  <link name="left_motor">
    <visual>
      <geometry>
            <box size="0.0465 0.034 0.0285"/>
      </geometry>
      <material name="grey"/>
    </visual>

    <collision>
        <geometry>
            <box size="0.0465 0.034 0.0285"/>
        </geometry>
    </collision>
  
    <inertial>
        <mass value="0.05"/>
        <origin rpy="0 0 0" xyz="0 0 0"/>
        <inertia ixx="8.201041666666668e-06" ixy="0" ixz="0" iyy="1.239375e-05" iyz="0" izz="1.3826041666666666e-05"/>
    </inertial>
  </link>

    <joint name="left_motor_joint" type="fixed">
        <origin rpy="0 0 0" xyz="-0.020 -0.05175 0.0175" />
        <parent link="first_plate" />
        <child link="left_motor" />
    </joint>

    <gazebo reference="left_motor">
        <material>Gazebo/Grey</material>
        <turnGravityOff>true</turnGravityOff>
    </gazebo>

  <!-- Left Wheel axle -->
    <link name="left_axle">      
        <visual>
            <origin rpy="0 1.5707 1.5707" xyz="0 0 0"/>
            <geometry>
                <cylinder length="0.00935" radius="0.01025"/>
            </geometry>
            <material name="grey"/>
        </visual>

        <collision>
            <origin rpy="0 1.5707 1.5707" xyz="0 0 0"/>
            <geometry>
                <cylinder length="0.00935" radius="0.01025"/>
            </geometry>
        </collision>

        <inertial>
            <origin rpy="0 1.5707 1.5707" xyz="0 0 0"/>
            <mass value="0.020"/>
            <inertia ixx="6.710166666666668e-07" ixy="0" ixz="0" iyy="6.710166666666668e-07" iyz="0" izz="1.0506250000000002e-06"/>
        </inertial>

    </link>

    <joint name="left_axle_joint" type="fixed">
        <origin rpy="0 0 0" xyz="-0.012 -0.014675 0.001"/>
        <child link="left_axle"/>
        <parent link="left_motor"/>
    </joint>

    <gazebo reference="left_axle">
        <material>Gazebo/Grey</material>
        <turnGravityOff>true</turnGravityOff>
    </gazebo>


  <!-- Left wheel-->
    <link name="left_wheel">      
        <visual>
            <origin rpy="0 1.5707 1.5707" xyz="0 0 0"/>
            <geometry>
                <cylinder length="0.0178" radius="0.033"/>
            </geometry>
            <material name="grey"/>
        </visual>

        <collision>
            <origin rpy="0 1.5707 1.5707" xyz="0 0 0"/>
            <geometry>
                <cylinder length="0.0178" radius="0.033"/>
            </geometry>
        </collision>

        <inertial>
            <origin rpy="0 1.5707 1.5707" xyz="0 0 0"/>
            <mass value="0.025"/>
            <inertia ixx="7.466333333333334e-06" ixy="0" ixz="0" iyy="7.466333333333334e-06" iyz="0" izz="1.3612500000000002e-05"/>
        </inertial>
    </link>

    <gazebo reference="left_wheel">
        <kp>1000000000000000000000000000.0</kp>
        <kd>1000000000000000000000000000.0</kd>
        <mu1>10.0</mu1>
        <mu2>10.0</mu2>
        <material>Gazebo/Grey</material>
        <turnGravityOff>true</turnGravityOff>
    </gazebo>

    <joint name="left_wheel_joint" type="continuous">
        <origin rpy="0 0 0" xyz="0 -0.013575 0"/>
        <child link="left_wheel"/>
        <parent link="left_axle"/>
        <axis rpy="0 0 0" xyz="0 1 0"/>
        <limit effort="10000" velocity="1000"/>
        <joint_properties damping="1.0" friction="1.0"/>
    </joint>


  <!-- Battery -->
  <link name="battery">
    <visual>
      <geometry>
        <box size="0.100 0.035 0.0275"/>
      </geometry>
      <material name="grey"/>
    </visual>

    <collision>
        <geometry>
            <box size="0.100 0.035 0.0275"/>
        </geometry>
    </collision>
  
    <inertial>
        <mass value="0.2"/>
        <origin rpy="0 0 0" xyz="0 0 0"/>
        <inertia ixx="3.302083333333334e-05" ixy="0" ixz="0" iyy="0.00017927083333333337" iyz="0" izz="0.00018708333333333337"/>
    </inertial>
  </link>

    <joint name="battery_joint" type="fixed">
        <origin rpy="0 0 0" xyz="0 0 0.01675" />
        <parent link="first_plate" />
        <child link="battery" />
    </joint>

    <gazebo reference="battery">
        <material>Gazebo/Grey</material>
        <turnGravityOff>true</turnGravityOff>
    </gazebo>

  <!-- Right rear spacer plate 1 -->
    <link name="right_rear_1">      
        <visual>
            <geometry>
                <cylinder length="0.035" radius="0.0025"/>
            </geometry>
            <material name="grey"/>
        </visual>

        <collision>
            <geometry>
                <cylinder length="0.035" radius="0.0025"/>
            </geometry>
        </collision>

        <inertial>
            <mass value="0.020"/>
            <inertia ixx="7.255208333333336e-07" ixy="0" ixz="0" iyy="7.255208333333336e-07" iyz="0" izz="2.1875000000000002e-08"/>
        </inertial>

    </link>

    <joint name="right_rear_1_joint" type="fixed">
        <origin rpy="0 0 0" xyz="-0.06125 0.024 0.0175"/>
        <child link="right_rear_1"/>
        <parent link="first_plate"/>
    </joint>

    <gazebo reference="right_rear_1">
        <material>Gazebo/Grey</material>
        <turnGravityOff>true</turnGravityOff>
    </gazebo>


  <!-- Right rear spacer plate 1 -->
    <link name="right_rear_spacer_1">      
        <visual>
            <geometry>
                <cylinder length="0.035" radius="0.0025"/>
            </geometry>
            <material name="grey"/>
        </visual>

        <collision>
            <geometry>
                <cylinder length="0.035" radius="0.0025"/>
            </geometry>
        </collision>

        <inertial>
            <mass value="0.020"/>
            <inertia ixx="7.255208333333336e-07" ixy="0" ixz="0" iyy="7.255208333333336e-07" iyz="0" izz="2.1875000000000002e-08"/>
        </inertial>

    </link>

    <joint name="right_rear_spacer_1_joint" type="fixed">
        <origin rpy="0 0 0" xyz="-0.06125 0.024 0.0175"/>
        <child link="right_rear_spacer_1"/>
        <parent link="first_plate"/>
    </joint>

    <gazebo reference="right_rear_spacer_1">
        <material>Gazebo/Grey</material>
        <turnGravityOff>true</turnGravityOff>
    </gazebo>


  <!-- Left rear spacer plate 1 -->
    <link name="left_rear_spacer_1">      
        <visual>
            <geometry>
                <cylinder length="0.035" radius="0.0025"/>
            </geometry>
            <material name="grey"/>
        </visual>

        <collision>
            <geometry>
                <cylinder length="0.035" radius="0.0025"/>
            </geometry>
        </collision>

        <inertial>
            <mass value="0.020"/>
            <inertia ixx="7.255208333333336e-07" ixy="0" ixz="0" iyy="7.255208333333336e-07" iyz="0" izz="2.1875000000000002e-08"/>
        </inertial>

    </link>

    <joint name="left_rear_spacer_1_joint" type="fixed">
        <origin rpy="0 0 0" xyz="-0.06125 -0.024 0.0175"/>
        <child link="left_rear_spacer_1"/>
        <parent link="first_plate"/>
    </joint>

    <gazebo reference="left_rear_spacer_1">
        <material>Gazebo/Grey</material>
        <turnGravityOff>true</turnGravityOff>
    </gazebo>


  <!-- Right front spacer plate 1 -->
    <link name="right_front_spacer_1">      
        <visual>
            <geometry>
                <cylinder length="0.035" radius="0.0025"/>
            </geometry>
            <material name="grey"/>
        </visual>

        <collision>
            <geometry>
                <cylinder length="0.035" radius="0.0025"/>
            </geometry>
        </collision>

        <inertial>
            <mass value="0.020"/>
            <inertia ixx="7.255208333333336e-07" ixy="0" ixz="0" iyy="7.255208333333336e-07" iyz="0" izz="2.1875000000000002e-08"/>
        </inertial>

    </link>

    <joint name="right_front_spacer_1_joint" type="fixed">
        <origin rpy="0 0 0" xyz="0.06125 0.024 0.0175"/>
        <child link="right_front_spacer_1"/>
        <parent link="first_plate"/>
    </joint>

    <gazebo reference="right_front_spacer_1">
        <material>Gazebo/Grey</material>
        <turnGravityOff>true</turnGravityOff>
    </gazebo>


  <!-- left front spacer plate 1 -->
    <link name="left_front_spacer_1">      
        <visual>
            <geometry>
                <cylinder length="0.035" radius="0.0025"/>
            </geometry>
            <material name="grey"/>
        </visual>

        <collision>
            <geometry>
                <cylinder length="0.035" radius="0.0025"/>
            </geometry>
        </collision>

        <inertial>
            <mass value="0.020"/>
            <inertia ixx="7.255208333333336e-07" ixy="0" ixz="0" iyy="7.255208333333336e-07" iyz="0" izz="2.1875000000000002e-08"/>
        </inertial>

    </link>

    <joint name="left_front_spacer_1_joint" type="fixed">
        <origin rpy="0 0 0" xyz="0.06125 -0.024 0.0175"/>
        <child link="left_front_spacer_1"/>
        <parent link="first_plate"/>
    </joint>

    <gazebo reference="left_front_spacer_1">
        <material>Gazebo/Grey</material>
        <turnGravityOff>true</turnGravityOff>
    </gazebo>


  <!-- Cater wheel support -->
  <link name="caster_support">
    <visual>
      <geometry>
        <box size="0.030 0.018 0.008"/>
      </geometry>
      <material name="grey"/>
    </visual>

    <collision>
        <geometry>
            <box size="0.030 0.018 0.008"/>
        </geometry>
    </collision>
  
    <inertial>
        <mass value="0.010"/>
        <origin rpy="0 0 0" xyz="0 0 0"/>
        <inertia ixx="3.23333333e-07" ixy="0" ixz="0" iyy="8.03333333e-07" iyz="0" izz="1.02000000e-06"/>
    </inertial>
  </link>

    <joint name="caster_support_joint" type="fixed">
        <origin rpy="0 0 0" xyz="0.049 0 -0.0045" />
        <parent link="first_plate" />
        <child link="caster_support" />
    </joint>

    <gazebo reference="caster_support">
        <material>Gazebo/Grey</material>
        <turnGravityOff>true</turnGravityOff>
    </gazebo>

  <!-- Caster Wheel -->
    <link name="caster_yaw">
        <visual>
            <origin rpy="0 1.5707 1.5707" xyz="0 0 0"/>
            <geometry>          
                <cylinder length="0.001" radius="0.0045000000000000005"/>
            </geometry>
            <material name="blue"/>
        </visual>

        <collision>
            <origin rpy="0 1.5707 1.5707" xyz="0 0 0"/>
            <geometry>
                <cylinder length="0.001" radius="0.0045000000000000005"/>
            </geometry>
        </collision>

        <inertial>
            <origin rpy="0 1.5707 1.5707" xyz="0 0 0"/>
            <mass value="0.001"/>
            <inertia ixx="5.145833333333334e-09" ixy="0" ixz="0" iyy="5.145833333333334e-09" iyz="0" izz="1.0125000000000003e-08"/>
        </inertial>

    </link>

    <joint name="caster_yaw_joint" type="continuous">
        <origin rpy="0 0 0" xyz="0 0 -0.005" />
        <parent link="caster_support" />
        <child link="caster_yaw" />
        <axis xyz="0 0 1" />
        <limit effort="1000.0" velocity="100.0" />
        <dynamics damping="0.0" friction="0.1"/>
    </joint>

    <gazebo reference="caster_yaw">
        <material>Gazebo/Blue</material>
        <turnGravityOff>true</turnGravityOff>
    </gazebo>


    <link name="caster_roll">
        <visual>
            <origin rpy="0 1.5707 1.5707" xyz="0 0 0"/>
            <geometry>
                <cylinder length="0.001" radius="0.0045000000000000005"/>
            </geometry>
            <material name="red"/>
        </visual>

        <collision>
            <origin rpy="0 1.5707 1.5707" xyz="0 0 0"/>
            <geometry>
                <cylinder length="0.001" radius="0.0045000000000000005"/>
            </geometry>
        </collision>

        <inertial>
            <origin rpy="0 1.5707 1.5707" xyz="0 0 0"/>
            <mass value="0.001"/>
            <inertia ixx="5.145833333333334e-09" ixy="0" ixz="0" iyy="5.145833333333334e-09" iyz="0" izz="1.0125000000000003e-08"/>
        </inertial>
    </link>

    <joint name="caster_roll_joint" type="continuous">
        <origin rpy="0 0 0" xyz="0 0 0" />
        <parent link="caster_yaw" />
        <child link="caster_roll" />
        <axis xyz="1 0 0" />
        <limit effort="1000.0" velocity="100.0" />
        <dynamics damping="0.0" friction="0.1"/>
    </joint>


    <link name="caster_pitch">
        <visual>
            <origin rpy="0 1.5707 1.5707" xyz="0 0 0"/>
            <geometry>
                <sphere radius="0.005"/>
            </geometry>
            <material name="green_dark"/>
        </visual>

        <collision>
            <origin rpy="0 1.5707 1.5707" xyz="0 0 0"/>
            <geometry>
            <sphere radius="0.005"/>
            </geometry>
        </collision>

        <inertial>
            <origin rpy="0 1.5707 1.5707" xyz="0 0 0"/>
            <mass value="0.01"/>
            <inertia ixx="1.00000000e-07" ixy="0" ixz="0" iyy="1.00000000e-07" iyz="0" izz="1.00000000e-07"/>
        </inertial>
    </link>

    <gazebo reference="caster_pitch">
        <kp>1000000000000000000000000000.0</kp>
        <kd>1000000000000000000000000000.0</kd>
        <mu1>0.5</mu1>
        <mu2>0.5</mu2>
        <material>Gazebo/Purple</material>
        <turnGravityOff>true</turnGravityOff>
    </gazebo>
    
    <joint name="caster_pitch_joint" type="continuous">
        <origin rpy="0 0 0" xyz="0 0 0" />
        <parent link="caster_roll" />
        <child link="caster_pitch" />
        <axis xyz="0 1 0" />
        <limit effort="1000.0" velocity="100.0" />
        <dynamics damping="0.0" friction="0.1"/>
    </joint>
 
  <!-- Second Plate -->
  <link name="second_plate">
    <visual>
      <geometry>
        <box size="0.1375 0.1375 0.009"/>
      </geometry>
      <material name="black"/>
    </visual>

    <collision>
        <geometry>
          <box size="0.1357 0.1357 0.009"/>
        </geometry>
    </collision>
  
    <inertial>
        <mass value="0.035"/>
        <origin rpy="0 0 0" xyz="0 0 0"/>
        <inertia ixx="5.537947916666668e-05" ixy="0" ixz="0" iyy="5.537947916666668e-05" iyz="0" izz="0.00011028645833333336"/>
    </inertial>
  </link>

    <joint name="second_plate_joint" type="fixed">
        <origin rpy="0 0 0" xyz="0 0 35" />
        <parent link="first_plate" />
        <child link="second_plate" />
    </joint>

    <gazebo reference="second_plate">
        <material>Gazebo/Black</material>
        <turnGravityOff>true</turnGravityOff>
    </gazebo>
</robot>